<?xml version="1.0" ?>
<!-- =================================================================================== -->
<!-- |    This document was autogenerated by xacro from adaptive_gripper.xacro         | -->
<!-- |    EDITING THIS FILE BY HAND IS NOT RECOMMENDED                                 | -->
<!-- =================================================================================== -->
<robot name="adaptive_gripper" xmlns:xacro="http://www.ros.org/wiki/xacro">
  <!-- Links -->
  <link name="palm">
    <visual>
      <geometry>
        <box size="0.014 0.05 0.1"/>
      </geometry>
    </visual>
  </link>
  <link name="left_proximal">
    <visual>
      <geometry>
        <box size="0.014 0.014 0.05"/>
      </geometry>
      <origin xyz="0 0 0.025"/>
    </visual>
  </link>
  <link name="right_proximal">
    <visual>
      <geometry>
        <box size="0.014 0.014 0.05"/>
      </geometry>
      <origin xyz="0 0 0.025"/>
    </visual>
  </link>
  <link name="left_finger">
    <visual>
      <geometry>
        <box size="0.014 0.014 0.02"/>
      </geometry>
      <origin xyz="0 0 0.01"/>
    </visual>
  </link>
  <link name="right_finger">
    <visual>
      <geometry>
        <box size="0.014 0.014 0.02"/>
      </geometry>
      <origin xyz="0 0 0.01"/>
    </visual>
  </link>
  <!-- Joints -->
  <joint name="palm_to_left_proximal" type="revolute">
    <parent link="palm"/>
    <child link="left_proximal"/>
    <limit effort="1000.0" lower="-1.52" upper="1.52" velocity="1.0"/>
    <origin xyz="0 -0.005 0.03"/>
    <axis xyz="-1 0 0"/>
  </joint>
  <joint name="palm_to_right_proximal" type="revolute">
    <parent link="palm"/>
    <child link="right_proximal"/>
    <limit effort="1000.0" lower="-1.52" upper="1.52" velocity="1.0"/>
    <origin xyz="0 0.005 0.03"/>
    <axis xyz="-1 0 0"/>
  </joint>
  <joint name="left_proximal_to_finger" type="revolute">
    <parent link="left_proximal"/>
    <child link="left_finger"/>
    <limit effort="1000.0" lower="-1.52" upper="1.52" velocity="1.0"/>
    <origin xyz=" 0 0 0.05"/>
    <axis xyz="-1 0 0"/>
  </joint>
  <joint name="right_proximal_to_finger" type="revolute">
    <parent link="right_proximal"/>
    <child link="right_finger"/>
    <limit effort="1000.0" lower="-1.52" upper="1.52" velocity="1.0"/>
    <origin xyz=" 0 0 0.05"/>
    <axis xyz="-1 0 0"/>
  </joint>
</robot>
